<?xml version="1.0" ?>
<robot name="turtlebot3_happy_mini" xmlns:xacro="http://ros.org/wiki/xacro">
  <!-- <xacro:include filename="$(find turtlebot3_description)/urdf/common_properties.urdf"/> -->

  <!-- Init colour -->
  <material name="black">
      <color rgba="0.0 0.0 0.0 1.0"/>
  </material>

  <material name="dark">
    <color rgba="0.3 0.3 0.3 1.0"/>
  </material>

  <material name="light_black">
    <color rgba="0.4 0.4 0.4 1.0"/>
  </material>

  <material name="blue">
    <color rgba="0.0 0.0 0.8 1.0"/>
  </material>

  <material name="green">
    <color rgba="0.0 0.8 0.0 1.0"/>
  </material>

  <material name="grey">
    <color rgba="0.5 0.5 0.5 1.0"/>
  </material>

  <material name="orange">
    <color rgba="1.0 0.4235 0.0392 1.0"/>
  </material>

  <material name="brown">
    <color rgba="0.8706 0.8118 0.7647 1.0"/>
  </material>

  <material name="red">
    <color rgba="0.8 0.0 0.0 1.0"/>
  </material>

  <material name="white">
    <color rgba="1.0 1.0 1.0 1.0"/>
  </material>

  <link name="base_footprint"/>

  <joint name="base_joint" type="fixed">
    <parent link="base_footprint"/>
    <child link="base_link" />
    <origin xyz="0 0 0.010" rpy="0 0 0"/>
  </joint>

  <link name="base_link">
    <inertial>
      <origin xyz="0 0 0" rpy="0 0 0"/>
      <mass value="1.3729096e+00"/>
      <inertia ixx="4.2111447e-02" ixy="0" ixz="0"
               iyy="4.2111447e-02" iyz="0"
               izz="7.5254874e-02" />
    </inertial>

    <collision name="base_collision">
      <origin xyz="0.015 0 0.55" rpy="0 0 0"/>
      <geometry>
        <cylinder radius="0.18" length="1.1"/>
      </geometry>
    </collision>

    <visual name="base_visual">
      <origin xyz="-0.064 -0.142 -0.03" rpy="0 0 1.55"/>
      <geometry>
        <mesh filename="package://turtlebot3_description/meshes/happy_mini/base_mini.dae" scale="0.01 0.01 0.01"/>
      </geometry>
    </visual>

    <visual name="head_visual">
      <origin xyz="-0.297 -0.139 0.049" rpy="0.314 0 1.57"/>
      <geometry>
        <mesh filename="package://turtlebot3_description/meshes/happy_mini/head_mini.dae" scale="0.01 0.01 0.01"/>
      </geometry>
    </visual>

    <visual name="torso_upper_visual">
      <origin xyz="-0.047 -0.14 -0.03" rpy="0 0 1.57"/>
      <geometry>
        <mesh filename="package://turtlebot3_description/meshes/happy_mini/torso_upper_mini.dae" scale="0.01 0.01 0.01"/>
      </geometry>
    </visual>

    <visual name="torso_lower_visual">
      <origin xyz="-0.047 -0.14 -0.03" rpy="0 0 1.57"/>
      <geometry>
        <mesh filename="package://turtlebot3_description/meshes/happy_mini/torso_lower_mini.dae" scale="0.01 0.01 0.01"/>
      </geometry>
    </visual>

    <visual name="arm_upper_visual">
      <origin xyz="0.102 0.004 0.32" rpy="0 1.57 0"/>
      <geometry>
        <mesh filename="package://turtlebot3_description/meshes/happy_mini/arm_mini.dae" scale="0.01 0.01 0.01"/>
      </geometry>
    </visual>

    <visual name="hand_left_visual">
      <origin xyz="0.102 0.003 0.34" rpy="0 1.57 0"/>
      <geometry>
        <mesh filename="package://turtlebot3_description/meshes/happy_mini/hand_left_mini.dae" scale="0.01 0.01 0.01"/>
      </geometry>
    </visual>

    <visual name="hand_right_visual">
      <origin xyz="0.104  0.003 0.34" rpy="0 1.57 0"/>
      <geometry>
        <mesh filename="package://turtlebot3_description/meshes/happy_mini/hand_right_mini.dae" scale="0.01 0.01 0.01"/>
      </geometry>
    </visual>

    <visual name="wrist_visual">
      <origin xyz="0.102 0.003 0.322" rpy="0 1.57 0"/>
      <geometry>
        <mesh filename="package://turtlebot3_description/meshes/happy_mini/wrist_mini.dae" scale="0.01 0.01 0.01"/>
      </geometry>
    </visual>

  </link>

  <joint name="wheel_left_joint" type="continuous">
    <parent link="base_link"/>
    <child link="wheel_left_link"/>
    <origin xyz="0.0 0.144 0.023" rpy="-1.57 0 0"/>
    <axis xyz="0 0 1"/>
  </joint>

  <link name="wheel_left_link">
    <inertial>
      <origin xyz="0 0 0" />
      <mass value="2.8498940e-02" />
      <inertia ixx="1.1175580e-05" ixy="-4.2369783e-11" ixz="-5.9381719e-09"
               iyy="1.1192413e-05" iyz="-1.4400107e-11"
               izz="2.0712558e-05" />
    </inertial>

    <collision>
      <origin xyz="0 0 0" rpy="0 0 0"/>
      <geometry>
        <cylinder length="0.018" radius="0.033"/>
      </geometry>
    </collision>

    <visual>
      <origin xyz="0 0 0" rpy="1.57 0 0"/>
      <geometry>
        <mesh filename="package://turtlebot3_description/meshes/wheels/left_tire.stl" scale="0.001 0.001 0.001"/>
      </geometry>
      <material name="dark"/>
    </visual>
  </link>

  <joint name="wheel_right_joint" type="continuous">
    <parent link="base_link"/>
    <child link="wheel_right_link"/>
    <origin xyz="0.0 -0.144 0.023" rpy="-1.57 0 0"/>
    <axis xyz="0 0 1"/>
  </joint>

  <link name="wheel_right_link">
    <visual>
      <origin xyz="0 0 0" rpy="1.57 0 0"/>
      <geometry>
        <mesh filename="package://turtlebot3_description/meshes/wheels/right_tire.stl" scale="0.001 0.001 0.001"/>
      </geometry>
      <material name="dark"/>
    </visual>

    <collision>
      <origin xyz="0 0 0" rpy="0 0 0"/>
      <geometry>
        <cylinder length="0.018" radius="0.033"/>
      </geometry>
    </collision>

    <inertial>
      <origin xyz="0 0 0" />
      <mass value="2.8498940e-02" />
      <inertia ixx="1.1175580e-05" ixy="-4.2369783e-11" ixz="-5.9381719e-09"
               iyy="1.1192413e-05" iyz="-1.4400107e-11"
               izz="2.0712558e-05" />
      </inertial>
  </link>

  <joint name="caster_back_joint" type="fixed">
    <parent link="base_link"/>
    <child link="caster_back_link"/>
    <origin xyz="-0.144 0.0 -0.004" rpy="0 0 0"/>
  </joint>

  <link name="caster_back_link">
    <inertial>
      <origin xyz="0 0 0" />
      <mass value="0.001" />
      <inertia ixx="0.00001" ixy="0.0" ixz="0.0"
               iyy="0.00001" iyz="0.0"
               izz="0.00001" />
    </inertial>

    <collision>
      <origin xyz="0 0 0" rpy="0 0 0"/>
      <geometry>
        <sphere radius="0.005"/>
      </geometry>
    </collision>
  </link>

  <joint name="caster_front_joint" type="fixed">
    <parent link="base_link"/>
    <child link="caster_front_link"/>
    <origin xyz="0.144 0.0 -0.004" rpy="0 0 0"/>
  </joint>

  <link name="caster_front_link">
    <inertial>
      <origin xyz="0 0 0" />
      <mass value="0.001" />
      <inertia ixx="0.00001" ixy="0.0" ixz="0.0"
               iyy="0.00001" iyz="0.0"
               izz="0.00001" />
    </inertial>

    <collision>
      <origin xyz="0 0 0" rpy="0 0 0"/>
      <geometry>
        <sphere radius="0.005"/>
      </geometry>
    </collision>
  </link>

  <joint name="imu_joint" type="fixed">
    <parent link="base_link"/>
    <child link="imu_link"/>
    <origin xyz="-0.032 0 0.068" rpy="0 0 0"/>
  </joint>

  <link name="imu_link"/>

  <joint name="scan_joint" type="fixed">
    <parent link="base_link"/>
    <child link="base_scan"/>
    <origin xyz="0.14 0 0.121" rpy="0 0 0"/>
  </joint>

  <link name="base_scan">
    <inertial>
      <mass value="0.114" />
      <origin xyz="0 0 0" />
      <inertia ixx="0.001" ixy="0.0" ixz="0.0"
               iyy="0.001" iyz="0.0"
               izz="0.001" />
    </inertial>

    <visual>
      <origin xyz="0 0 0" rpy="0 0 0"/>
      <geometry>
        <mesh filename="package://turtlebot3_description/meshes/happy_mini/lidar.dae"
              scale="1 1 1"/>
      </geometry>
    </visual>

    <collision>
      <origin xyz="0 0 0.013" rpy="0 0 0"/>
      <geometry>
        <box size="0.06 0.06 0.087"/>
      </geometry>
    </collision>
  </link>

  <joint name="camera_joint" type="fixed">
    <origin xyz="0.08 0 1.03" rpy="0 0 0"/>
    <parent link="base_link"/>
    <child link="camera_link"/>
  </joint>

  <link name="camera_link">
    <inertial>
      <mass value="0.035" />
      <origin xyz="0 0 0" />
      <inertia ixx="0.001" ixy="0.0" ixz="0.0"
               iyy="0.001" iyz="0.0"
               izz="0.001" />
    </inertial>

    <collision>
      <origin xyz="0 0 0" rpy="0 0 0"/>
      <geometry>
        <box size="0.04 0.18 0.025"/>
      </geometry>
    </collision>
  </link>

  <joint name="camera_rgb_joint" type="fixed">
    <origin xyz="0.0 0.0 0.0" rpy="-1.57 0 -1.57"/>
    <parent link="camera_link"/>
    <child link="camera_rgb_optical_frame"/>
  </joint>

  <link name="camera_rgb_optical_frame"/>

</robot>
